[2023-09-30 16:52:50 +0100] [914] [DEBUG] Current configuration:
  config: gunicorn_config.py
  wsgi_app: backend.wsgi:application
  bind: ['0.0.0.0:8000']
  backlog: 2048
  workers: 3
  worker_class: sync
  threads: 1
  worker_connections: 1000
  max_requests: 0
  max_requests_jitter: 0
  timeout: 30
  graceful_timeout: 30
  keepalive: 2
  limit_request_line: 4094
  limit_request_fields: 100
  limit_request_field_size: 8190
  reload: True
  reload_engine: auto
  reload_extra_files: []
  spew: False
  check_config: False
  print_config: False
  preload_app: False
  sendfile: None
  reuse_port: False
  chdir: /mnt/c/Users/USER/Desktop/web/findme/backend
  daemon: True
  raw_env: []
  pidfile: ./gunicorn/dev.pid
  worker_tmp_dir: None
  user: 1000
  group: 1000
  umask: 0
  initgroups: False
  tmp_upload_dir: None
  secure_scheme_headers: {'X-FORWARDED-PROTOCOL': 'ssl', 'X-FORWARDED-PROTO': 'https', 'X-FORWARDED-SSL': 'on'}
  forwarded_allow_ips: ['127.0.0.1']
  accesslog: ./gunicorn/dev.log
  disable_redirect_access_to_syslog: False
  access_log_format: %(h)s %(l)s %(u)s %(t)s "%(r)s" %(s)s %(b)s "%(f)s" "%(a)s"
  errorlog: ./gunicorn/dev.log
  loglevel: debug
  capture_output: True
  logger_class: gunicorn.glogging.Logger
  logconfig: None
  logconfig_dict: {}
  logconfig_json: None
  syslog_addr: udp://localhost:514
  syslog: False
  syslog_prefix: None
  syslog_facility: user
  enable_stdio_inheritance: False
  statsd_host: None
  dogstatsd_tags: 
  statsd_prefix: 
  proc_name: None
  default_proc_name: gunicorn
  pythonpath: None
  paste: None
  on_starting: <function OnStarting.on_starting at 0x7f93960b03a0>
  on_reload: <function OnReload.on_reload at 0x7f93960b04c0>
  when_ready: <function WhenReady.when_ready at 0x7f93960b05e0>
  pre_fork: <function Prefork.pre_fork at 0x7f93960b0700>
  post_fork: <function Postfork.post_fork at 0x7f93960b0820>
  post_worker_init: <function PostWorkerInit.post_worker_init at 0x7f93960b0940>
  worker_int: <function WorkerInt.worker_int at 0x7f93960b0a60>
  worker_abort: <function WorkerAbort.worker_abort at 0x7f93960b0b80>
  pre_exec: <function PreExec.pre_exec at 0x7f93960b0ca0>
  pre_request: <function PreRequest.pre_request at 0x7f93960b0dc0>
  post_request: <function PostRequest.post_request at 0x7f93960b0e50>
  child_exit: <function ChildExit.child_exit at 0x7f93960b0f70>
  worker_exit: <function WorkerExit.worker_exit at 0x7f93960480d0>
  nworkers_changed: <function NumWorkersChanged.nworkers_changed at 0x7f93960481f0>
  on_exit: <function OnExit.on_exit at 0x7f9396048310>
  ssl_context: <function NewSSLContext.ssl_context at 0x7f9396048430>
  proxy_protocol: False
  proxy_allow_ips: ['127.0.0.1']
  keyfile: None
  certfile: None
  ssl_version: 2
  cert_reqs: 0
  ca_certs: None
  suppress_ragged_eofs: True
  do_handshake_on_connect: False
  ciphers: None
  raw_paste_global_conf: []
  strip_header_spaces: False
[2023-09-30 16:52:50 +0100] [914] [INFO] Starting gunicorn 21.2.0
[2023-09-30 16:52:50 +0100] [914] [DEBUG] Arbiter booted
[2023-09-30 16:52:50 +0100] [914] [INFO] Listening at: http://0.0.0.0:8000 (914)
[2023-09-30 16:52:50 +0100] [914] [INFO] Using worker: sync
[2023-09-30 16:52:50 +0100] [916] [INFO] Booting worker with pid: 916
[2023-09-30 16:52:50 +0100] [917] [INFO] Booting worker with pid: 917
[2023-09-30 16:52:50 +0100] [918] [INFO] Booting worker with pid: 918
[2023-09-30 16:52:50 +0100] [914] [DEBUG] 3 workers
[2023-09-30 16:52:51 +0100] [918] [ERROR] Exception in worker process
Traceback (most recent call last):
  File "/mnt/c/Users/USER/Desktop/web/findme/.ubuntu/lib/python3.8/site-packages/gunicorn/arbiter.py", line 609, in spawn_worker
    worker.init_process()
  File "/mnt/c/Users/USER/Desktop/web/findme/.ubuntu/lib/python3.8/site-packages/gunicorn/workers/base.py", line 134, in init_process
    self.load_wsgi()
  File "/mnt/c/Users/USER/Desktop/web/findme/.ubuntu/lib/python3.8/site-packages/gunicorn/workers/base.py", line 146, in load_wsgi
    self.wsgi = self.app.wsgi()
  File "/mnt/c/Users/USER/Desktop/web/findme/.ubuntu/lib/python3.8/site-packages/gunicorn/app/base.py", line 67, in wsgi
    self.callable = self.load()
  File "/mnt/c/Users/USER/Desktop/web/findme/.ubuntu/lib/python3.8/site-packages/gunicorn/app/wsgiapp.py", line 58, in load
    return self.load_wsgiapp()
  File "/mnt/c/Users/USER/Desktop/web/findme/.ubuntu/lib/python3.8/site-packages/gunicorn/app/wsgiapp.py", line 48, in load_wsgiapp
    return util.import_app(self.app_uri)
  File "/mnt/c/Users/USER/Desktop/web/findme/.ubuntu/lib/python3.8/site-packages/gunicorn/util.py", line 371, in import_app
    mod = importlib.import_module(module)
  File "/usr/lib/python3.8/importlib/__init__.py", line 127, in import_module
    return _bootstrap._gcd_import(name[level:], package, level)
  File "<frozen importlib._bootstrap>", line 1014, in _gcd_import
  File "<frozen importlib._bootstrap>", line 991, in _find_and_load
  File "<frozen importlib._bootstrap>", line 975, in _find_and_load_unlocked
  File "<frozen importlib._bootstrap>", line 671, in _load_unlocked
  File "<frozen importlib._bootstrap_external>", line 783, in exec_module
  File "<frozen importlib._bootstrap>", line 219, in _call_with_frames_removed
  File "/mnt/c/Users/USER/Desktop/web/findme/backend/backend/wsgi.py", line 12, in <module>
    from django.core.wsgi import get_wsgi_application
  File "/mnt/c/Users/USER/Desktop/web/findme/.ubuntu/lib/python3.8/site-packages/django/__init__.py", line 1, in <module>
    from django.utils.version import get_version
ModuleNotFoundError: No module named 'django.utils'
[2023-09-30 16:52:51 +0100] [917] [ERROR] Exception in worker process
Traceback (most recent call last):
  File "/mnt/c/Users/USER/Desktop/web/findme/.ubuntu/lib/python3.8/site-packages/gunicorn/arbiter.py", line 609, in spawn_worker
    worker.init_process()
  File "/mnt/c/Users/USER/Desktop/web/findme/.ubuntu/lib/python3.8/site-packages/gunicorn/workers/base.py", line 134, in init_process
    self.load_wsgi()
  File "/mnt/c/Users/USER/Desktop/web/findme/.ubuntu/lib/python3.8/site-packages/gunicorn/workers/base.py", line 146, in load_wsgi
    self.wsgi = self.app.wsgi()
  File "/mnt/c/Users/USER/Desktop/web/findme/.ubuntu/lib/python3.8/site-packages/gunicorn/app/base.py", line 67, in wsgi
    self.callable = self.load()
  File "/mnt/c/Users/USER/Desktop/web/findme/.ubuntu/lib/python3.8/site-packages/gunicorn/app/wsgiapp.py", line 58, in load
    return self.load_wsgiapp()
  File "/mnt/c/Users/USER/Desktop/web/findme/.ubuntu/lib/python3.8/site-packages/gunicorn/app/wsgiapp.py", line 48, in load_wsgiapp
    return util.import_app(self.app_uri)
  File "/mnt/c/Users/USER/Desktop/web/findme/.ubuntu/lib/python3.8/site-packages/gunicorn/util.py", line 371, in import_app
    mod = importlib.import_module(module)
  File "/usr/lib/python3.8/importlib/__init__.py", line 127, in import_module
    return _bootstrap._gcd_import(name[level:], package, level)
  File "<frozen importlib._bootstrap>", line 1014, in _gcd_import
  File "<frozen importlib._bootstrap>", line 991, in _find_and_load
  File "<frozen importlib._bootstrap>", line 975, in _find_and_load_unlocked
  File "<frozen importlib._bootstrap>", line 671, in _load_unlocked
  File "<frozen importlib._bootstrap_external>", line 783, in exec_module
  File "<frozen importlib._bootstrap>", line 219, in _call_with_frames_removed
  File "/mnt/c/Users/USER/Desktop/web/findme/backend/backend/wsgi.py", line 12, in <module>
    from django.core.wsgi import get_wsgi_application
  File "/mnt/c/Users/USER/Desktop/web/findme/.ubuntu/lib/python3.8/site-packages/django/__init__.py", line 1, in <module>
    from django.utils.version import get_version
ModuleNotFoundError: No module named 'django.utils'
[2023-09-30 16:52:51 +0100] [918] [INFO] Worker exiting (pid: 918)
[2023-09-30 16:52:51 +0100] [917] [INFO] Worker exiting (pid: 917)
[2023-09-30 16:52:51 +0100] [916] [ERROR] Exception in worker process
Traceback (most recent call last):
  File "/mnt/c/Users/USER/Desktop/web/findme/.ubuntu/lib/python3.8/site-packages/gunicorn/arbiter.py", line 609, in spawn_worker
    worker.init_process()
  File "/mnt/c/Users/USER/Desktop/web/findme/.ubuntu/lib/python3.8/site-packages/gunicorn/workers/base.py", line 134, in init_process
    self.load_wsgi()
  File "/mnt/c/Users/USER/Desktop/web/findme/.ubuntu/lib/python3.8/site-packages/gunicorn/workers/base.py", line 146, in load_wsgi
    self.wsgi = self.app.wsgi()
  File "/mnt/c/Users/USER/Desktop/web/findme/.ubuntu/lib/python3.8/site-packages/gunicorn/app/base.py", line 67, in wsgi
    self.callable = self.load()
  File "/mnt/c/Users/USER/Desktop/web/findme/.ubuntu/lib/python3.8/site-packages/gunicorn/app/wsgiapp.py", line 58, in load
    return self.load_wsgiapp()
  File "/mnt/c/Users/USER/Desktop/web/findme/.ubuntu/lib/python3.8/site-packages/gunicorn/app/wsgiapp.py", line 48, in load_wsgiapp
    return util.import_app(self.app_uri)
  File "/mnt/c/Users/USER/Desktop/web/findme/.ubuntu/lib/python3.8/site-packages/gunicorn/util.py", line 371, in import_app
    mod = importlib.import_module(module)
  File "/usr/lib/python3.8/importlib/__init__.py", line 127, in import_module
    return _bootstrap._gcd_import(name[level:], package, level)
  File "<frozen importlib._bootstrap>", line 1014, in _gcd_import
  File "<frozen importlib._bootstrap>", line 991, in _find_and_load
  File "<frozen importlib._bootstrap>", line 975, in _find_and_load_unlocked
  File "<frozen importlib._bootstrap>", line 671, in _load_unlocked
  File "<frozen importlib._bootstrap_external>", line 783, in exec_module
  File "<frozen importlib._bootstrap>", line 219, in _call_with_frames_removed
  File "/mnt/c/Users/USER/Desktop/web/findme/backend/backend/wsgi.py", line 12, in <module>
    from django.core.wsgi import get_wsgi_application
  File "/mnt/c/Users/USER/Desktop/web/findme/.ubuntu/lib/python3.8/site-packages/django/__init__.py", line 1, in <module>
    from django.utils.version import get_version
ModuleNotFoundError: No module named 'django.utils'
[2023-09-30 16:52:51 +0100] [916] [INFO] Worker exiting (pid: 916)
[2023-09-30 16:52:51 +0100] [914] [ERROR] Worker (pid:917) exited with code 3
[2023-09-30 16:52:51 +0100] [914] [ERROR] Worker (pid:916) was sent SIGTERM!
[2023-09-30 16:52:52 +0100] [914] [ERROR] Worker (pid:918) was sent SIGTERM!
[2023-09-30 16:52:52 +0100] [914] [ERROR] Shutting down: Master
[2023-09-30 16:52:52 +0100] [914] [ERROR] Reason: Worker failed to boot.
[2023-09-30 17:03:01 +0100] [956] [DEBUG] Current configuration:
  config: gunicorn_config.py
  wsgi_app: backend.wsgi:application
  bind: ['0.0.0.0:8000']
  backlog: 2048
  workers: 3
  worker_class: sync
  threads: 1
  worker_connections: 1000
  max_requests: 0
  max_requests_jitter: 0
  timeout: 30
  graceful_timeout: 30
  keepalive: 2
  limit_request_line: 4094
  limit_request_fields: 100
  limit_request_field_size: 8190
  reload: True
  reload_engine: auto
  reload_extra_files: []
  spew: False
  check_config: False
  print_config: False
  preload_app: False
  sendfile: None
  reuse_port: False
  chdir: /mnt/c/Users/USER/Desktop/web/findme/backend
  daemon: True
  raw_env: []
  pidfile: ./gunicorn/dev.pid
  worker_tmp_dir: None
  user: 1000
  group: 1000
  umask: 0
  initgroups: False
  tmp_upload_dir: None
  secure_scheme_headers: {'X-FORWARDED-PROTOCOL': 'ssl', 'X-FORWARDED-PROTO': 'https', 'X-FORWARDED-SSL': 'on'}
  forwarded_allow_ips: ['127.0.0.1']
  accesslog: ./gunicorn/dev.log
  disable_redirect_access_to_syslog: False
  access_log_format: %(h)s %(l)s %(u)s %(t)s "%(r)s" %(s)s %(b)s "%(f)s" "%(a)s"
  errorlog: ./gunicorn/dev.log
  loglevel: debug
  capture_output: True
  logger_class: gunicorn.glogging.Logger
  logconfig: None
  logconfig_dict: {}
  logconfig_json: None
  syslog_addr: udp://localhost:514
  syslog: False
  syslog_prefix: None
  syslog_facility: user
  enable_stdio_inheritance: False
  statsd_host: None
  dogstatsd_tags: 
  statsd_prefix: 
  proc_name: None
  default_proc_name: gunicorn
  pythonpath: None
  paste: None
  on_starting: <function OnStarting.on_starting at 0x7f0b70cee3a0>
  on_reload: <function OnReload.on_reload at 0x7f0b70cee4c0>
  when_ready: <function WhenReady.when_ready at 0x7f0b70cee5e0>
  pre_fork: <function Prefork.pre_fork at 0x7f0b70cee700>
  post_fork: <function Postfork.post_fork at 0x7f0b70cee820>
  post_worker_init: <function PostWorkerInit.post_worker_init at 0x7f0b70cee940>
  worker_int: <function WorkerInt.worker_int at 0x7f0b70ceea60>
  worker_abort: <function WorkerAbort.worker_abort at 0x7f0b70ceeb80>
  pre_exec: <function PreExec.pre_exec at 0x7f0b70ceeca0>
  pre_request: <function PreRequest.pre_request at 0x7f0b70ceedc0>
  post_request: <function PostRequest.post_request at 0x7f0b70ceee50>
  child_exit: <function ChildExit.child_exit at 0x7f0b70ceef70>
  worker_exit: <function WorkerExit.worker_exit at 0x7f0b70c860d0>
  nworkers_changed: <function NumWorkersChanged.nworkers_changed at 0x7f0b70c861f0>
  on_exit: <function OnExit.on_exit at 0x7f0b70c86310>
  ssl_context: <function NewSSLContext.ssl_context at 0x7f0b70c86430>
  proxy_protocol: False
  proxy_allow_ips: ['127.0.0.1']
  keyfile: None
  certfile: None
  ssl_version: 2
  cert_reqs: 0
  ca_certs: None
  suppress_ragged_eofs: True
  do_handshake_on_connect: False
  ciphers: None
  raw_paste_global_conf: []
  strip_header_spaces: False
[2023-09-30 17:03:01 +0100] [956] [INFO] Starting gunicorn 21.2.0
[2023-09-30 17:03:01 +0100] [956] [DEBUG] Arbiter booted
[2023-09-30 17:03:01 +0100] [956] [INFO] Listening at: http://0.0.0.0:8000 (956)
[2023-09-30 17:03:01 +0100] [956] [INFO] Using worker: sync
[2023-09-30 17:03:01 +0100] [958] [INFO] Booting worker with pid: 958
[2023-09-30 17:03:01 +0100] [959] [INFO] Booting worker with pid: 959
[2023-09-30 17:03:01 +0100] [960] [INFO] Booting worker with pid: 960
[2023-09-30 17:03:01 +0100] [956] [DEBUG] 3 workers
[2023-09-30 17:03:01 +0100] [959] [ERROR] Exception in worker process
Traceback (most recent call last):
  File "/mnt/c/Users/USER/Desktop/web/findme/.ubuntu/lib/python3.8/site-packages/gunicorn/arbiter.py", line 609, in spawn_worker
    worker.init_process()
  File "/mnt/c/Users/USER/Desktop/web/findme/.ubuntu/lib/python3.8/site-packages/gunicorn/workers/base.py", line 134, in init_process
    self.load_wsgi()
  File "/mnt/c/Users/USER/Desktop/web/findme/.ubuntu/lib/python3.8/site-packages/gunicorn/workers/base.py", line 146, in load_wsgi
    self.wsgi = self.app.wsgi()
  File "/mnt/c/Users/USER/Desktop/web/findme/.ubuntu/lib/python3.8/site-packages/gunicorn/app/base.py", line 67, in wsgi
    self.callable = self.load()
  File "/mnt/c/Users/USER/Desktop/web/findme/.ubuntu/lib/python3.8/site-packages/gunicorn/app/wsgiapp.py", line 58, in load
    return self.load_wsgiapp()
  File "/mnt/c/Users/USER/Desktop/web/findme/.ubuntu/lib/python3.8/site-packages/gunicorn/app/wsgiapp.py", line 48, in load_wsgiapp
    return util.import_app(self.app_uri)
  File "/mnt/c/Users/USER/Desktop/web/findme/.ubuntu/lib/python3.8/site-packages/gunicorn/util.py", line 371, in import_app
    mod = importlib.import_module(module)
  File "/usr/lib/python3.8/importlib/__init__.py", line 127, in import_module
    return _bootstrap._gcd_import(name[level:], package, level)
  File "<frozen importlib._bootstrap>", line 1014, in _gcd_import
  File "<frozen importlib._bootstrap>", line 991, in _find_and_load
  File "<frozen importlib._bootstrap>", line 975, in _find_and_load_unlocked
  File "<frozen importlib._bootstrap>", line 671, in _load_unlocked
  File "<frozen importlib._bootstrap_external>", line 783, in exec_module
  File "<frozen importlib._bootstrap>", line 219, in _call_with_frames_removed
  File "/mnt/c/Users/USER/Desktop/web/findme/backend/backend/wsgi.py", line 12, in <module>
    from django.core.wsgi import get_wsgi_application
  File "/mnt/c/Users/USER/Desktop/web/findme/.ubuntu/lib/python3.8/site-packages/django/__init__.py", line 1, in <module>
    from django.utils.version import get_version
ModuleNotFoundError: No module named 'django.utils'
[2023-09-30 17:03:01 +0100] [960] [ERROR] Exception in worker process
Traceback (most recent call last):
  File "/mnt/c/Users/USER/Desktop/web/findme/.ubuntu/lib/python3.8/site-packages/gunicorn/arbiter.py", line 609, in spawn_worker
    worker.init_process()
  File "/mnt/c/Users/USER/Desktop/web/findme/.ubuntu/lib/python3.8/site-packages/gunicorn/workers/base.py", line 134, in init_process
    self.load_wsgi()
  File "/mnt/c/Users/USER/Desktop/web/findme/.ubuntu/lib/python3.8/site-packages/gunicorn/workers/base.py", line 146, in load_wsgi
    self.wsgi = self.app.wsgi()
  File "/mnt/c/Users/USER/Desktop/web/findme/.ubuntu/lib/python3.8/site-packages/gunicorn/app/base.py", line 67, in wsgi
    self.callable = self.load()
  File "/mnt/c/Users/USER/Desktop/web/findme/.ubuntu/lib/python3.8/site-packages/gunicorn/app/wsgiapp.py", line 58, in load
    return self.load_wsgiapp()
  File "/mnt/c/Users/USER/Desktop/web/findme/.ubuntu/lib/python3.8/site-packages/gunicorn/app/wsgiapp.py", line 48, in load_wsgiapp
    return util.import_app(self.app_uri)
  File "/mnt/c/Users/USER/Desktop/web/findme/.ubuntu/lib/python3.8/site-packages/gunicorn/util.py", line 371, in import_app
    mod = importlib.import_module(module)
  File "/usr/lib/python3.8/importlib/__init__.py", line 127, in import_module
    return _bootstrap._gcd_import(name[level:], package, level)
  File "<frozen importlib._bootstrap>", line 1014, in _gcd_import
  File "<frozen importlib._bootstrap>", line 991, in _find_and_load
  File "<frozen importlib._bootstrap>", line 975, in _find_and_load_unlocked
  File "<frozen importlib._bootstrap>", line 671, in _load_unlocked
  File "<frozen importlib._bootstrap_external>", line 783, in exec_module
  File "<frozen importlib._bootstrap>", line 219, in _call_with_frames_removed
  File "/mnt/c/Users/USER/Desktop/web/findme/backend/backend/wsgi.py", line 12, in <module>
    from django.core.wsgi import get_wsgi_application
  File "/mnt/c/Users/USER/Desktop/web/findme/.ubuntu/lib/python3.8/site-packages/django/__init__.py", line 1, in <module>
    from django.utils.version import get_version
ModuleNotFoundError: No module named 'django.utils'
[2023-09-30 17:03:02 +0100] [959] [INFO] Worker exiting (pid: 959)
[2023-09-30 17:03:02 +0100] [960] [INFO] Worker exiting (pid: 960)
[2023-09-30 17:03:01 +0100] [958] [ERROR] Exception in worker process
Traceback (most recent call last):
  File "/mnt/c/Users/USER/Desktop/web/findme/.ubuntu/lib/python3.8/site-packages/gunicorn/arbiter.py", line 609, in spawn_worker
    worker.init_process()
  File "/mnt/c/Users/USER/Desktop/web/findme/.ubuntu/lib/python3.8/site-packages/gunicorn/workers/base.py", line 134, in init_process
    self.load_wsgi()
  File "/mnt/c/Users/USER/Desktop/web/findme/.ubuntu/lib/python3.8/site-packages/gunicorn/workers/base.py", line 146, in load_wsgi
    self.wsgi = self.app.wsgi()
  File "/mnt/c/Users/USER/Desktop/web/findme/.ubuntu/lib/python3.8/site-packages/gunicorn/app/base.py", line 67, in wsgi
    self.callable = self.load()
  File "/mnt/c/Users/USER/Desktop/web/findme/.ubuntu/lib/python3.8/site-packages/gunicorn/app/wsgiapp.py", line 58, in load
    return self.load_wsgiapp()
  File "/mnt/c/Users/USER/Desktop/web/findme/.ubuntu/lib/python3.8/site-packages/gunicorn/app/wsgiapp.py", line 48, in load_wsgiapp
    return util.import_app(self.app_uri)
  File "/mnt/c/Users/USER/Desktop/web/findme/.ubuntu/lib/python3.8/site-packages/gunicorn/util.py", line 371, in import_app
    mod = importlib.import_module(module)
  File "/usr/lib/python3.8/importlib/__init__.py", line 127, in import_module
    return _bootstrap._gcd_import(name[level:], package, level)
  File "<frozen importlib._bootstrap>", line 1014, in _gcd_import
  File "<frozen importlib._bootstrap>", line 991, in _find_and_load
  File "<frozen importlib._bootstrap>", line 975, in _find_and_load_unlocked
  File "<frozen importlib._bootstrap>", line 671, in _load_unlocked
  File "<frozen importlib._bootstrap_external>", line 783, in exec_module
  File "<frozen importlib._bootstrap>", line 219, in _call_with_frames_removed
  File "/mnt/c/Users/USER/Desktop/web/findme/backend/backend/wsgi.py", line 12, in <module>
    from django.core.wsgi import get_wsgi_application
  File "/mnt/c/Users/USER/Desktop/web/findme/.ubuntu/lib/python3.8/site-packages/django/__init__.py", line 1, in <module>
    from django.utils.version import get_version
ModuleNotFoundError: No module named 'django.utils'
[2023-09-30 17:03:02 +0100] [958] [INFO] Worker exiting (pid: 958)
[2023-09-30 17:03:02 +0100] [956] [ERROR] Worker (pid:959) exited with code 3
[2023-09-30 17:03:02 +0100] [956] [ERROR] Worker (pid:958) was sent SIGTERM!
[2023-09-30 17:03:02 +0100] [956] [ERROR] Worker (pid:960) was sent SIGTERM!
[2023-09-30 17:03:02 +0100] [956] [ERROR] Shutting down: Master
[2023-09-30 17:03:02 +0100] [956] [ERROR] Reason: Worker failed to boot.
[2023-09-30 17:04:48 +0100] [997] [DEBUG] Current configuration:
  config: gunicorn_config.py
  wsgi_app: backend.wsgi:application
  bind: ['0.0.0.0:8000']
  backlog: 2048
  workers: 3
  worker_class: sync
  threads: 1
  worker_connections: 1000
  max_requests: 0
  max_requests_jitter: 0
  timeout: 30
  graceful_timeout: 30
  keepalive: 2
  limit_request_line: 4094
  limit_request_fields: 100
  limit_request_field_size: 8190
  reload: True
  reload_engine: auto
  reload_extra_files: []
  spew: False
  check_config: False
  print_config: False
  preload_app: False
  sendfile: None
  reuse_port: False
  chdir: /mnt/c/Users/USER/Desktop/web/findme/backend
  daemon: True
  raw_env: []
  pidfile: ./gunicorn/dev.pid
  worker_tmp_dir: None
  user: 1000
  group: 1000
  umask: 0
  initgroups: False
  tmp_upload_dir: None
  secure_scheme_headers: {'X-FORWARDED-PROTOCOL': 'ssl', 'X-FORWARDED-PROTO': 'https', 'X-FORWARDED-SSL': 'on'}
  forwarded_allow_ips: ['127.0.0.1']
  accesslog: ./gunicorn/dev.log
  disable_redirect_access_to_syslog: False
  access_log_format: %(h)s %(l)s %(u)s %(t)s "%(r)s" %(s)s %(b)s "%(f)s" "%(a)s"
  errorlog: ./gunicorn/dev.log
  loglevel: debug
  capture_output: True
  logger_class: gunicorn.glogging.Logger
  logconfig: None
  logconfig_dict: {}
  logconfig_json: None
  syslog_addr: udp://localhost:514
  syslog: False
  syslog_prefix: None
  syslog_facility: user
  enable_stdio_inheritance: False
  statsd_host: None
  dogstatsd_tags: 
  statsd_prefix: 
  proc_name: None
  default_proc_name: gunicorn
  pythonpath: None
  paste: None
  on_starting: <function OnStarting.on_starting at 0x7f88e4620550>
  on_reload: <function OnReload.on_reload at 0x7f88e4620670>
  when_ready: <function WhenReady.when_ready at 0x7f88e4620790>
  pre_fork: <function Prefork.pre_fork at 0x7f88e46208b0>
  post_fork: <function Postfork.post_fork at 0x7f88e46209d0>
  post_worker_init: <function PostWorkerInit.post_worker_init at 0x7f88e4620af0>
  worker_int: <function WorkerInt.worker_int at 0x7f88e4620c10>
  worker_abort: <function WorkerAbort.worker_abort at 0x7f88e4620d30>
  pre_exec: <function PreExec.pre_exec at 0x7f88e4620e50>
  pre_request: <function PreRequest.pre_request at 0x7f88e4620f70>
  post_request: <function PostRequest.post_request at 0x7f88e4638040>
  child_exit: <function ChildExit.child_exit at 0x7f88e4638160>
  worker_exit: <function WorkerExit.worker_exit at 0x7f88e4638280>
  nworkers_changed: <function NumWorkersChanged.nworkers_changed at 0x7f88e46383a0>
  on_exit: <function OnExit.on_exit at 0x7f88e46384c0>
  ssl_context: <function NewSSLContext.ssl_context at 0x7f88e46385e0>
  proxy_protocol: False
  proxy_allow_ips: ['127.0.0.1']
  keyfile: None
  certfile: None
  ssl_version: 2
  cert_reqs: 0
  ca_certs: None
  suppress_ragged_eofs: True
  do_handshake_on_connect: False
  ciphers: None
  raw_paste_global_conf: []
  strip_header_spaces: False
[2023-09-30 17:04:48 +0100] [997] [INFO] Starting gunicorn 21.2.0
[2023-09-30 17:04:48 +0100] [997] [DEBUG] Arbiter booted
[2023-09-30 17:04:48 +0100] [997] [INFO] Listening at: http://0.0.0.0:8000 (997)
[2023-09-30 17:04:48 +0100] [997] [INFO] Using worker: sync
[2023-09-30 17:04:48 +0100] [999] [INFO] Booting worker with pid: 999
[2023-09-30 17:04:48 +0100] [1000] [INFO] Booting worker with pid: 1000
[2023-09-30 17:04:48 +0100] [1001] [INFO] Booting worker with pid: 1001
[2023-09-30 17:04:48 +0100] [997] [DEBUG] 3 workers
[2023-09-30 17:04:48 +0100] [999] [ERROR] Exception in worker process
Traceback (most recent call last):
  File "/mnt/c/Users/USER/Desktop/web/findme/.ubuntu/lib/python3.8/site-packages/gunicorn/arbiter.py", line 609, in spawn_worker
    worker.init_process()
  File "/mnt/c/Users/USER/Desktop/web/findme/.ubuntu/lib/python3.8/site-packages/gunicorn/workers/base.py", line 134, in init_process
    self.load_wsgi()
  File "/mnt/c/Users/USER/Desktop/web/findme/.ubuntu/lib/python3.8/site-packages/gunicorn/workers/base.py", line 146, in load_wsgi
    self.wsgi = self.app.wsgi()
  File "/mnt/c/Users/USER/Desktop/web/findme/.ubuntu/lib/python3.8/site-packages/gunicorn/app/base.py", line 67, in wsgi
    self.callable = self.load()
  File "/mnt/c/Users/USER/Desktop/web/findme/.ubuntu/lib/python3.8/site-packages/gunicorn/app/wsgiapp.py", line 58, in load
    return self.load_wsgiapp()
  File "/mnt/c/Users/USER/Desktop/web/findme/.ubuntu/lib/python3.8/site-packages/gunicorn/app/wsgiapp.py", line 48, in load_wsgiapp
    return util.import_app(self.app_uri)
  File "/mnt/c/Users/USER/Desktop/web/findme/.ubuntu/lib/python3.8/site-packages/gunicorn/util.py", line 371, in import_app
    mod = importlib.import_module(module)
  File "/usr/lib/python3.8/importlib/__init__.py", line 127, in import_module
    return _bootstrap._gcd_import(name[level:], package, level)
  File "<frozen importlib._bootstrap>", line 1014, in _gcd_import
  File "<frozen importlib._bootstrap>", line 991, in _find_and_load
  File "<frozen importlib._bootstrap>", line 975, in _find_and_load_unlocked
  File "<frozen importlib._bootstrap>", line 671, in _load_unlocked
  File "<frozen importlib._bootstrap_external>", line 783, in exec_module
  File "<frozen importlib._bootstrap>", line 219, in _call_with_frames_removed
  File "/mnt/c/Users/USER/Desktop/web/findme/backend/backend/wsgi.py", line 12, in <module>
    from django.core.wsgi import get_wsgi_application
  File "/mnt/c/Users/USER/Desktop/web/findme/.ubuntu/lib/python3.8/site-packages/django/__init__.py", line 1, in <module>
    from django.utils.version import get_version
ModuleNotFoundError: No module named 'django.utils'
[2023-09-30 17:04:48 +0100] [999] [INFO] Worker exiting (pid: 999)
[2023-09-30 17:04:48 +0100] [1000] [ERROR] Exception in worker process
Traceback (most recent call last):
  File "/mnt/c/Users/USER/Desktop/web/findme/.ubuntu/lib/python3.8/site-packages/gunicorn/arbiter.py", line 609, in spawn_worker
    worker.init_process()
  File "/mnt/c/Users/USER/Desktop/web/findme/.ubuntu/lib/python3.8/site-packages/gunicorn/workers/base.py", line 134, in init_process
    self.load_wsgi()
  File "/mnt/c/Users/USER/Desktop/web/findme/.ubuntu/lib/python3.8/site-packages/gunicorn/workers/base.py", line 146, in load_wsgi
    self.wsgi = self.app.wsgi()
  File "/mnt/c/Users/USER/Desktop/web/findme/.ubuntu/lib/python3.8/site-packages/gunicorn/app/base.py", line 67, in wsgi
    self.callable = self.load()
  File "/mnt/c/Users/USER/Desktop/web/findme/.ubuntu/lib/python3.8/site-packages/gunicorn/app/wsgiapp.py", line 58, in load
    return self.load_wsgiapp()
  File "/mnt/c/Users/USER/Desktop/web/findme/.ubuntu/lib/python3.8/site-packages/gunicorn/app/wsgiapp.py", line 48, in load_wsgiapp
    return util.import_app(self.app_uri)
  File "/mnt/c/Users/USER/Desktop/web/findme/.ubuntu/lib/python3.8/site-packages/gunicorn/util.py", line 371, in import_app
    mod = importlib.import_module(module)
  File "/usr/lib/python3.8/importlib/__init__.py", line 127, in import_module
    return _bootstrap._gcd_import(name[level:], package, level)
  File "<frozen importlib._bootstrap>", line 1014, in _gcd_import
  File "<frozen importlib._bootstrap>", line 991, in _find_and_load
  File "<frozen importlib._bootstrap>", line 975, in _find_and_load_unlocked
  File "<frozen importlib._bootstrap>", line 671, in _load_unlocked
  File "<frozen importlib._bootstrap_external>", line 783, in exec_module
  File "<frozen importlib._bootstrap>", line 219, in _call_with_frames_removed
  File "/mnt/c/Users/USER/Desktop/web/findme/backend/backend/wsgi.py", line 12, in <module>
    from django.core.wsgi import get_wsgi_application
  File "/mnt/c/Users/USER/Desktop/web/findme/.ubuntu/lib/python3.8/site-packages/django/__init__.py", line 1, in <module>
    from django.utils.version import get_version
ModuleNotFoundError: No module named 'django.utils'
[2023-09-30 17:04:48 +0100] [1000] [INFO] Worker exiting (pid: 1000)
[2023-09-30 17:04:48 +0100] [997] [ERROR] Worker (pid:999) exited with code 3
[2023-09-30 17:04:48 +0100] [997] [ERROR] Worker (pid:1000) was sent SIGTERM!
[2023-09-30 17:04:48 +0100] [1001] [ERROR] Exception in worker process
Traceback (most recent call last):
  File "/mnt/c/Users/USER/Desktop/web/findme/.ubuntu/lib/python3.8/site-packages/gunicorn/arbiter.py", line 609, in spawn_worker
    worker.init_process()
  File "/mnt/c/Users/USER/Desktop/web/findme/.ubuntu/lib/python3.8/site-packages/gunicorn/workers/base.py", line 134, in init_process
    self.load_wsgi()
  File "/mnt/c/Users/USER/Desktop/web/findme/.ubuntu/lib/python3.8/site-packages/gunicorn/workers/base.py", line 146, in load_wsgi
    self.wsgi = self.app.wsgi()
  File "/mnt/c/Users/USER/Desktop/web/findme/.ubuntu/lib/python3.8/site-packages/gunicorn/app/base.py", line 67, in wsgi
    self.callable = self.load()
  File "/mnt/c/Users/USER/Desktop/web/findme/.ubuntu/lib/python3.8/site-packages/gunicorn/app/wsgiapp.py", line 58, in load
    return self.load_wsgiapp()
  File "/mnt/c/Users/USER/Desktop/web/findme/.ubuntu/lib/python3.8/site-packages/gunicorn/app/wsgiapp.py", line 48, in load_wsgiapp
    return util.import_app(self.app_uri)
  File "/mnt/c/Users/USER/Desktop/web/findme/.ubuntu/lib/python3.8/site-packages/gunicorn/util.py", line 371, in import_app
    mod = importlib.import_module(module)
  File "/usr/lib/python3.8/importlib/__init__.py", line 127, in import_module
    return _bootstrap._gcd_import(name[level:], package, level)
  File "<frozen importlib._bootstrap>", line 1014, in _gcd_import
  File "<frozen importlib._bootstrap>", line 991, in _find_and_load
  File "<frozen importlib._bootstrap>", line 975, in _find_and_load_unlocked
  File "<frozen importlib._bootstrap>", line 671, in _load_unlocked
  File "<frozen importlib._bootstrap_external>", line 783, in exec_module
  File "<frozen importlib._bootstrap>", line 219, in _call_with_frames_removed
  File "/mnt/c/Users/USER/Desktop/web/findme/backend/backend/wsgi.py", line 12, in <module>
    from django.core.wsgi import get_wsgi_application
  File "/mnt/c/Users/USER/Desktop/web/findme/.ubuntu/lib/python3.8/site-packages/django/__init__.py", line 1, in <module>
    from django.utils.version import get_version
ModuleNotFoundError: No module named 'django.utils'
[2023-09-30 17:04:48 +0100] [1001] [INFO] Worker exiting (pid: 1001)
[2023-09-30 17:04:48 +0100] [997] [ERROR] Worker (pid:1001) exited with code 3
Traceback (most recent call last):
  File "/mnt/c/Users/USER/Desktop/web/findme/.ubuntu/lib/python3.8/site-packages/gunicorn/arbiter.py", line 209, in run
    self.sleep()
  File "/mnt/c/Users/USER/Desktop/web/findme/.ubuntu/lib/python3.8/site-packages/gunicorn/arbiter.py", line 360, in sleep
    ready = select.select([self.PIPE[0]], [], [], 1.0)
  File "/mnt/c/Users/USER/Desktop/web/findme/.ubuntu/lib/python3.8/site-packages/gunicorn/arbiter.py", line 242, in handle_chld
    self.reap_workers()
  File "/mnt/c/Users/USER/Desktop/web/findme/.ubuntu/lib/python3.8/site-packages/gunicorn/arbiter.py", line 530, in reap_workers
    raise HaltServer(reason, self.WORKER_BOOT_ERROR)
gunicorn.errors.HaltServer: <HaltServer 'Worker failed to boot.' 3>

During handling of the above exception, another exception occurred:

Traceback (most recent call last):
  File "/usr/lib/python3.8/runpy.py", line 193, in _run_module_as_main
    return _run_code(code, main_globals, None,
  File "/usr/lib/python3.8/runpy.py", line 86, in _run_code
    exec(code, run_globals)
  File "/mnt/c/Users/USER/Desktop/web/findme/.ubuntu/lib/python3.8/site-packages/gunicorn/__main__.py", line 7, in <module>
    run()
  File "/mnt/c/Users/USER/Desktop/web/findme/.ubuntu/lib/python3.8/site-packages/gunicorn/app/wsgiapp.py", line 67, in run
    WSGIApplication("%(prog)s [OPTIONS] [APP_MODULE]").run()
  File "/mnt/c/Users/USER/Desktop/web/findme/.ubuntu/lib/python3.8/site-packages/gunicorn/app/base.py", line 236, in run
    super().run()
  File "/mnt/c/Users/USER/Desktop/web/findme/.ubuntu/lib/python3.8/site-packages/gunicorn/app/base.py", line 72, in run
    Arbiter(self).run()
  File "/mnt/c/Users/USER/Desktop/web/findme/.ubuntu/lib/python3.8/site-packages/gunicorn/arbiter.py", line 229, in run
    self.halt(reason=inst.reason, exit_status=inst.exit_status)
  File "/mnt/c/Users/USER/Desktop/web/findme/.ubuntu/lib/python3.8/site-packages/gunicorn/arbiter.py", line 342, in halt
    self.stop()
  File "/mnt/c/Users/USER/Desktop/web/findme/.ubuntu/lib/python3.8/site-packages/gunicorn/arbiter.py", line 396, in stop
    time.sleep(0.1)
  File "/mnt/c/Users/USER/Desktop/web/findme/.ubuntu/lib/python3.8/site-packages/gunicorn/arbiter.py", line 242, in handle_chld
    self.reap_workers()
  File "/mnt/c/Users/USER/Desktop/web/findme/.ubuntu/lib/python3.8/site-packages/gunicorn/arbiter.py", line 530, in reap_workers
    raise HaltServer(reason, self.WORKER_BOOT_ERROR)
gunicorn.errors.HaltServer: <HaltServer 'Worker failed to boot.' 3>
[2023-09-30 17:05:27 +0100] [1010] [DEBUG] Current configuration:
  config: gunicorn_config.py
  wsgi_app: backend.wsgi:application
  bind: ['0.0.0.0:8000']
  backlog: 2048
  workers: 3
  worker_class: sync
  threads: 1
  worker_connections: 1000
  max_requests: 0
  max_requests_jitter: 0
  timeout: 30
  graceful_timeout: 30
  keepalive: 2
  limit_request_line: 4094
  limit_request_fields: 100
  limit_request_field_size: 8190
  reload: True
  reload_engine: auto
  reload_extra_files: []
  spew: False
  check_config: False
  print_config: False
  preload_app: False
  sendfile: None
  reuse_port: False
  chdir: /mnt/c/Users/USER/Desktop/web/findme/backend
  daemon: True
  raw_env: []
  pidfile: ./gunicorn/dev.pid
  worker_tmp_dir: None
  user: 1000
  group: 1000
  umask: 0
  initgroups: False
  tmp_upload_dir: None
  secure_scheme_headers: {'X-FORWARDED-PROTOCOL': 'ssl', 'X-FORWARDED-PROTO': 'https', 'X-FORWARDED-SSL': 'on'}
  forwarded_allow_ips: ['127.0.0.1']
  accesslog: ./gunicorn/dev.log
  disable_redirect_access_to_syslog: False
  access_log_format: %(h)s %(l)s %(u)s %(t)s "%(r)s" %(s)s %(b)s "%(f)s" "%(a)s"
  errorlog: ./gunicorn/dev.log
  loglevel: debug
  capture_output: True
  logger_class: gunicorn.glogging.Logger
  logconfig: None
  logconfig_dict: {}
  logconfig_json: None
  syslog_addr: udp://localhost:514
  syslog: False
  syslog_prefix: None
  syslog_facility: user
  enable_stdio_inheritance: False
  statsd_host: None
  dogstatsd_tags: 
  statsd_prefix: 
  proc_name: None
  default_proc_name: gunicorn
  pythonpath: None
  paste: None
  on_starting: <function OnStarting.on_starting at 0x7f7e0837a3a0>
  on_reload: <function OnReload.on_reload at 0x7f7e0837a4c0>
  when_ready: <function WhenReady.when_ready at 0x7f7e0837a5e0>
  pre_fork: <function Prefork.pre_fork at 0x7f7e0837a700>
  post_fork: <function Postfork.post_fork at 0x7f7e0837a820>
  post_worker_init: <function PostWorkerInit.post_worker_init at 0x7f7e0837a940>
  worker_int: <function WorkerInt.worker_int at 0x7f7e0837aa60>
  worker_abort: <function WorkerAbort.worker_abort at 0x7f7e0837ab80>
  pre_exec: <function PreExec.pre_exec at 0x7f7e0837aca0>
  pre_request: <function PreRequest.pre_request at 0x7f7e0837adc0>
  post_request: <function PostRequest.post_request at 0x7f7e0837ae50>
  child_exit: <function ChildExit.child_exit at 0x7f7e0837af70>
  worker_exit: <function WorkerExit.worker_exit at 0x7f7e083120d0>
  nworkers_changed: <function NumWorkersChanged.nworkers_changed at 0x7f7e083121f0>
  on_exit: <function OnExit.on_exit at 0x7f7e08312310>
  ssl_context: <function NewSSLContext.ssl_context at 0x7f7e08312430>
  proxy_protocol: False
  proxy_allow_ips: ['127.0.0.1']
  keyfile: None
  certfile: None
  ssl_version: 2
  cert_reqs: 0
  ca_certs: None
  suppress_ragged_eofs: True
  do_handshake_on_connect: False
  ciphers: None
  raw_paste_global_conf: []
  strip_header_spaces: False
[2023-09-30 17:05:27 +0100] [1010] [INFO] Starting gunicorn 21.2.0
[2023-09-30 17:05:27 +0100] [1010] [DEBUG] Arbiter booted
[2023-09-30 17:05:27 +0100] [1010] [INFO] Listening at: http://0.0.0.0:8000 (1010)
[2023-09-30 17:05:27 +0100] [1010] [INFO] Using worker: sync
[2023-09-30 17:05:27 +0100] [1012] [INFO] Booting worker with pid: 1012
[2023-09-30 17:05:27 +0100] [1013] [INFO] Booting worker with pid: 1013
[2023-09-30 17:05:27 +0100] [1014] [INFO] Booting worker with pid: 1014
[2023-09-30 17:05:27 +0100] [1012] [ERROR] Exception in worker process
Traceback (most recent call last):
  File "/mnt/c/Users/USER/Desktop/web/findme/.ubuntu/lib/python3.8/site-packages/gunicorn/arbiter.py", line 609, in spawn_worker
    worker.init_process()
  File "/mnt/c/Users/USER/Desktop/web/findme/.ubuntu/lib/python3.8/site-packages/gunicorn/workers/base.py", line 134, in init_process
    self.load_wsgi()
  File "/mnt/c/Users/USER/Desktop/web/findme/.ubuntu/lib/python3.8/site-packages/gunicorn/workers/base.py", line 146, in load_wsgi
    self.wsgi = self.app.wsgi()
  File "/mnt/c/Users/USER/Desktop/web/findme/.ubuntu/lib/python3.8/site-packages/gunicorn/app/base.py", line 67, in wsgi
    self.callable = self.load()
  File "/mnt/c/Users/USER/Desktop/web/findme/.ubuntu/lib/python3.8/site-packages/gunicorn/app/wsgiapp.py", line 58, in load
    return self.load_wsgiapp()
  File "/mnt/c/Users/USER/Desktop/web/findme/.ubuntu/lib/python3.8/site-packages/gunicorn/app/wsgiapp.py", line 48, in load_wsgiapp
    return util.import_app(self.app_uri)
  File "/mnt/c/Users/USER/Desktop/web/findme/.ubuntu/lib/python3.8/site-packages/gunicorn/util.py", line 371, in import_app
    mod = importlib.import_module(module)
  File "/usr/lib/python3.8/importlib/__init__.py", line 127, in import_module
    return _bootstrap._gcd_import(name[level:], package, level)
  File "<frozen importlib._bootstrap>", line 1014, in _gcd_import
  File "<frozen importlib._bootstrap>", line 991, in _find_and_load
  File "<frozen importlib._bootstrap>", line 975, in _find_and_load_unlocked
  File "<frozen importlib._bootstrap>", line 671, in _load_unlocked
  File "<frozen importlib._bootstrap_external>", line 783, in exec_module
  File "<frozen importlib._bootstrap>", line 219, in _call_with_frames_removed
  File "/mnt/c/Users/USER/Desktop/web/findme/backend/backend/wsgi.py", line 12, in <module>
    from django.core.wsgi import get_wsgi_application
  File "/mnt/c/Users/USER/Desktop/web/findme/.ubuntu/lib/python3.8/site-packages/django/__init__.py", line 1, in <module>
    from django.utils.version import get_version
ModuleNotFoundError: No module named 'django.utils'
[2023-09-30 17:05:27 +0100] [1013] [ERROR] Exception in worker process
Traceback (most recent call last):
  File "/mnt/c/Users/USER/Desktop/web/findme/.ubuntu/lib/python3.8/site-packages/gunicorn/arbiter.py", line 609, in spawn_worker
    worker.init_process()
  File "/mnt/c/Users/USER/Desktop/web/findme/.ubuntu/lib/python3.8/site-packages/gunicorn/workers/base.py", line 134, in init_process
    self.load_wsgi()
  File "/mnt/c/Users/USER/Desktop/web/findme/.ubuntu/lib/python3.8/site-packages/gunicorn/workers/base.py", line 146, in load_wsgi
    self.wsgi = self.app.wsgi()
  File "/mnt/c/Users/USER/Desktop/web/findme/.ubuntu/lib/python3.8/site-packages/gunicorn/app/base.py", line 67, in wsgi
    self.callable = self.load()
  File "/mnt/c/Users/USER/Desktop/web/findme/.ubuntu/lib/python3.8/site-packages/gunicorn/app/wsgiapp.py", line 58, in load
    return self.load_wsgiapp()
  File "/mnt/c/Users/USER/Desktop/web/findme/.ubuntu/lib/python3.8/site-packages/gunicorn/app/wsgiapp.py", line 48, in load_wsgiapp
    return util.import_app(self.app_uri)
  File "/mnt/c/Users/USER/Desktop/web/findme/.ubuntu/lib/python3.8/site-packages/gunicorn/util.py", line 371, in import_app
    mod = importlib.import_module(module)
  File "/usr/lib/python3.8/importlib/__init__.py", line 127, in import_module
    return _bootstrap._gcd_import(name[level:], package, level)
  File "<frozen importlib._bootstrap>", line 1014, in _gcd_import
  File "<frozen importlib._bootstrap>", line 991, in _find_and_load
  File "<frozen importlib._bootstrap>", line 975, in _find_and_load_unlocked
  File "<frozen importlib._bootstrap>", line 671, in _load_unlocked
  File "<frozen importlib._bootstrap_external>", line 783, in exec_module
  File "<frozen importlib._bootstrap>", line 219, in _call_with_frames_removed
  File "/mnt/c/Users/USER/Desktop/web/findme/backend/backend/wsgi.py", line 12, in <module>
    from django.core.wsgi import get_wsgi_application
  File "/mnt/c/Users/USER/Desktop/web/findme/.ubuntu/lib/python3.8/site-packages/django/__init__.py", line 1, in <module>
    from django.utils.version import get_version
ModuleNotFoundError: No module named 'django.utils'
[2023-09-30 17:05:27 +0100] [1012] [INFO] Worker exiting (pid: 1012)
[2023-09-30 17:05:27 +0100] [1013] [INFO] Worker exiting (pid: 1013)
[2023-09-30 17:05:27 +0100] [1010] [DEBUG] 3 workers
[2023-09-30 17:05:27 +0100] [1010] [ERROR] Worker (pid:1013) exited with code 3
[2023-09-30 17:05:27 +0100] [1010] [ERROR] Worker (pid:1012) exited with code 3
Traceback (most recent call last):
  File "/mnt/c/Users/USER/Desktop/web/findme/.ubuntu/lib/python3.8/site-packages/gunicorn/arbiter.py", line 209, in run
    self.sleep()
  File "/mnt/c/Users/USER/Desktop/web/findme/.ubuntu/lib/python3.8/site-packages/gunicorn/arbiter.py", line 360, in sleep
    ready = select.select([self.PIPE[0]], [], [], 1.0)
  File "/mnt/c/Users/USER/Desktop/web/findme/.ubuntu/lib/python3.8/site-packages/gunicorn/arbiter.py", line 242, in handle_chld
    self.reap_workers()
  File "/mnt/c/Users/USER/Desktop/web/findme/.ubuntu/lib/python3.8/site-packages/gunicorn/arbiter.py", line 530, in reap_workers
    raise HaltServer(reason, self.WORKER_BOOT_ERROR)
gunicorn.errors.HaltServer: <HaltServer 'Worker failed to boot.' 3>

During handling of the above exception, another exception occurred:

Traceback (most recent call last):
  File "/mnt/c/Users/USER/Desktop/web/findme/.ubuntu/bin/gunicorn", line 8, in <module>
    sys.exit(run())
  File "/mnt/c/Users/USER/Desktop/web/findme/.ubuntu/lib/python3.8/site-packages/gunicorn/app/wsgiapp.py", line 67, in run
    WSGIApplication("%(prog)s [OPTIONS] [APP_MODULE]").run()
  File "/mnt/c/Users/USER/Desktop/web/findme/.ubuntu/lib/python3.8/site-packages/gunicorn/app/base.py", line 236, in run
    super().run()
  File "/mnt/c/Users/USER/Desktop/web/findme/.ubuntu/lib/python3.8/site-packages/gunicorn/app/base.py", line 72, in run
    Arbiter(self).run()
  File "/mnt/c/Users/USER/Desktop/web/findme/.ubuntu/lib/python3.8/site-packages/gunicorn/arbiter.py", line 229, in run
[2023-09-30 17:05:27 +0100] [1014] [ERROR] Exception in worker process
Traceback (most recent call last):
  File "/mnt/c/Users/USER/Desktop/web/findme/.ubuntu/lib/python3.8/site-packages/gunicorn/arbiter.py", line 609, in spawn_worker
    worker.init_process()
  File "/mnt/c/Users/USER/Desktop/web/findme/.ubuntu/lib/python3.8/site-packages/gunicorn/workers/base.py", line 134, in init_process
    self.load_wsgi()
  File "/mnt/c/Users/USER/Desktop/web/findme/.ubuntu/lib/python3.8/site-packages/gunicorn/workers/base.py", line 146, in load_wsgi
    self.wsgi = self.app.wsgi()
  File "/mnt/c/Users/USER/Desktop/web/findme/.ubuntu/lib/python3.8/site-packages/gunicorn/app/base.py", line 67, in wsgi
    self.callable = self.load()
  File "/mnt/c/Users/USER/Desktop/web/findme/.ubuntu/lib/python3.8/site-packages/gunicorn/app/wsgiapp.py", line 58, in load
    return self.load_wsgiapp()
  File "/mnt/c/Users/USER/Desktop/web/findme/.ubuntu/lib/python3.8/site-packages/gunicorn/app/wsgiapp.py", line 48, in load_wsgiapp
    return util.import_app(self.app_uri)
  File "/mnt/c/Users/USER/Desktop/web/findme/.ubuntu/lib/python3.8/site-packages/gunicorn/util.py", line 371, in import_app
    mod = importlib.import_module(module)
  File "/usr/lib/python3.8/importlib/__init__.py", line 127, in import_module
    return _bootstrap._gcd_import(name[level:], package, level)
  File "<frozen importlib._bootstrap>", line 1014, in _gcd_import
  File "<frozen importlib._bootstrap>", line 991, in _find_and_load
  File "<frozen importlib._bootstrap>", line 975, in _find_and_load_unlocked
  File "<frozen importlib._bootstrap>", line 671, in _load_unlocked
  File "<frozen importlib._bootstrap_external>", line 783, in exec_module
  File "<frozen importlib._bootstrap>", line 219, in _call_with_frames_removed
  File "/mnt/c/Users/USER/Desktop/web/findme/backend/backend/wsgi.py", line 12, in <module>
    from django.core.wsgi import get_wsgi_application
  File "/mnt/c/Users/USER/Desktop/web/findme/.ubuntu/lib/python3.8/site-packages/django/__init__.py", line 1, in <module>
    from django.utils.version import get_version
ModuleNotFoundError: No module named 'django.utils'
[2023-09-30 17:05:27 +0100] [1014] [INFO] Worker exiting (pid: 1014)
    self.halt(reason=inst.reason, exit_status=inst.exit_status)
  File "/mnt/c/Users/USER/Desktop/web/findme/.ubuntu/lib/python3.8/site-packages/gunicorn/arbiter.py", line 342, in halt
    self.stop()
  File "/mnt/c/Users/USER/Desktop/web/findme/.ubuntu/lib/python3.8/site-packages/gunicorn/arbiter.py", line 396, in stop
    time.sleep(0.1)
  File "/mnt/c/Users/USER/Desktop/web/findme/.ubuntu/lib/python3.8/site-packages/gunicorn/arbiter.py", line 242, in handle_chld
    self.reap_workers()
  File "/mnt/c/Users/USER/Desktop/web/findme/.ubuntu/lib/python3.8/site-packages/gunicorn/arbiter.py", line 530, in reap_workers
    raise HaltServer(reason, self.WORKER_BOOT_ERROR)
gunicorn.errors.HaltServer: <HaltServer 'Worker failed to boot.' 3>
[2023-09-30 17:05:46 +0100] [1023] [DEBUG] Current configuration:
  config: gunicorn_config.py
  wsgi_app: backend.wsgi:application
  bind: ['127.0.0.1:8000']
  backlog: 2048
  workers: 3
  worker_class: sync
  threads: 1
  worker_connections: 1000
  max_requests: 0
  max_requests_jitter: 0
  timeout: 30
  graceful_timeout: 30
  keepalive: 2
  limit_request_line: 4094
  limit_request_fields: 100
  limit_request_field_size: 8190
  reload: True
  reload_engine: auto
  reload_extra_files: []
  spew: False
  check_config: False
  print_config: False
  preload_app: False
  sendfile: None
  reuse_port: False
  chdir: /mnt/c/Users/USER/Desktop/web/findme/backend
  daemon: True
  raw_env: []
  pidfile: ./gunicorn/dev.pid
  worker_tmp_dir: None
  user: 1000
  group: 1000
  umask: 0
  initgroups: False
  tmp_upload_dir: None
  secure_scheme_headers: {'X-FORWARDED-PROTOCOL': 'ssl', 'X-FORWARDED-PROTO': 'https', 'X-FORWARDED-SSL': 'on'}
  forwarded_allow_ips: ['127.0.0.1']
  accesslog: ./gunicorn/dev.log
  disable_redirect_access_to_syslog: False
  access_log_format: %(h)s %(l)s %(u)s %(t)s "%(r)s" %(s)s %(b)s "%(f)s" "%(a)s"
  errorlog: ./gunicorn/dev.log
  loglevel: debug
  capture_output: True
  logger_class: gunicorn.glogging.Logger
  logconfig: None
  logconfig_dict: {}
  logconfig_json: None
  syslog_addr: udp://localhost:514
  syslog: False
  syslog_prefix: None
  syslog_facility: user
  enable_stdio_inheritance: False
  statsd_host: None
  dogstatsd_tags: 
  statsd_prefix: 
  proc_name: None
  default_proc_name: gunicorn
  pythonpath: None
  paste: None
  on_starting: <function OnStarting.on_starting at 0x7ff8e51f03a0>
  on_reload: <function OnReload.on_reload at 0x7ff8e51f04c0>
  when_ready: <function WhenReady.when_ready at 0x7ff8e51f05e0>
  pre_fork: <function Prefork.pre_fork at 0x7ff8e51f0700>
  post_fork: <function Postfork.post_fork at 0x7ff8e51f0820>
  post_worker_init: <function PostWorkerInit.post_worker_init at 0x7ff8e51f0940>
  worker_int: <function WorkerInt.worker_int at 0x7ff8e51f0a60>
  worker_abort: <function WorkerAbort.worker_abort at 0x7ff8e51f0b80>
  pre_exec: <function PreExec.pre_exec at 0x7ff8e51f0ca0>
  pre_request: <function PreRequest.pre_request at 0x7ff8e51f0dc0>
  post_request: <function PostRequest.post_request at 0x7ff8e51f0e50>
  child_exit: <function ChildExit.child_exit at 0x7ff8e51f0f70>
  worker_exit: <function WorkerExit.worker_exit at 0x7ff8e51880d0>
  nworkers_changed: <function NumWorkersChanged.nworkers_changed at 0x7ff8e51881f0>
  on_exit: <function OnExit.on_exit at 0x7ff8e5188310>
  ssl_context: <function NewSSLContext.ssl_context at 0x7ff8e5188430>
  proxy_protocol: False
  proxy_allow_ips: ['127.0.0.1']
  keyfile: None
  certfile: None
  ssl_version: 2
  cert_reqs: 0
  ca_certs: None
  suppress_ragged_eofs: True
  do_handshake_on_connect: False
  ciphers: None
  raw_paste_global_conf: []
  strip_header_spaces: False
[2023-09-30 17:05:46 +0100] [1023] [INFO] Starting gunicorn 21.2.0
[2023-09-30 17:05:46 +0100] [1023] [DEBUG] Arbiter booted
[2023-09-30 17:05:46 +0100] [1023] [INFO] Listening at: http://127.0.0.1:8000 (1023)
[2023-09-30 17:05:46 +0100] [1023] [INFO] Using worker: sync
[2023-09-30 17:05:46 +0100] [1025] [INFO] Booting worker with pid: 1025
[2023-09-30 17:05:46 +0100] [1026] [INFO] Booting worker with pid: 1026
[2023-09-30 17:05:46 +0100] [1025] [ERROR] Exception in worker process
Traceback (most recent call last):
  File "/mnt/c/Users/USER/Desktop/web/findme/.ubuntu/lib/python3.8/site-packages/gunicorn/arbiter.py", line 609, in spawn_worker
    worker.init_process()
  File "/mnt/c/Users/USER/Desktop/web/findme/.ubuntu/lib/python3.8/site-packages/gunicorn/workers/base.py", line 134, in init_process
    self.load_wsgi()
  File "/mnt/c/Users/USER/Desktop/web/findme/.ubuntu/lib/python3.8/site-packages/gunicorn/workers/base.py", line 146, in load_wsgi
    self.wsgi = self.app.wsgi()
  File "/mnt/c/Users/USER/Desktop/web/findme/.ubuntu/lib/python3.8/site-packages/gunicorn/app/base.py", line 67, in wsgi
    self.callable = self.load()
  File "/mnt/c/Users/USER/Desktop/web/findme/.ubuntu/lib/python3.8/site-packages/gunicorn/app/wsgiapp.py", line 58, in load
    return self.load_wsgiapp()
  File "/mnt/c/Users/USER/Desktop/web/findme/.ubuntu/lib/python3.8/site-packages/gunicorn/app/wsgiapp.py", line 48, in load_wsgiapp
    return util.import_app(self.app_uri)
  File "/mnt/c/Users/USER/Desktop/web/findme/.ubuntu/lib/python3.8/site-packages/gunicorn/util.py", line 371, in import_app
    mod = importlib.import_module(module)
  File "/usr/lib/python3.8/importlib/__init__.py", line 127, in import_module
    return _bootstrap._gcd_import(name[level:], package, level)
  File "<frozen importlib._bootstrap>", line 1014, in _gcd_import
  File "<frozen importlib._bootstrap>", line 991, in _find_and_load
  File "<frozen importlib._bootstrap>", line 975, in _find_and_load_unlocked
  File "<frozen importlib._bootstrap>", line 671, in _load_unlocked
  File "<frozen importlib._bootstrap_external>", line 783, in exec_module
  File "<frozen importlib._bootstrap>", line 219, in _call_with_frames_removed
  File "/mnt/c/Users/USER/Desktop/web/findme/backend/backend/wsgi.py", line 12, in <module>
    from django.core.wsgi import get_wsgi_application
  File "/mnt/c/Users/USER/Desktop/web/findme/.ubuntu/lib/python3.8/site-packages/django/__init__.py", line 1, in <module>
    from django.utils.version import get_version
ModuleNotFoundError: No module named 'django.utils'
[2023-09-30 17:05:46 +0100] [1025] [INFO] Worker exiting (pid: 1025)
[2023-09-30 17:05:46 +0100] [1023] [ERROR] Worker (pid:1025) exited with code 3
[2023-09-30 17:05:46 +0100] [1026] [ERROR] Exception in worker process
Traceback (most recent call last):
  File "/mnt/c/Users/USER/Desktop/web/findme/.ubuntu/lib/python3.8/site-packages/gunicorn/arbiter.py", line 609, in spawn_worker
    worker.init_process()
  File "/mnt/c/Users/USER/Desktop/web/findme/.ubuntu/lib/python3.8/site-packages/gunicorn/workers/base.py", line 134, in init_process
    self.load_wsgi()
  File "/mnt/c/Users/USER/Desktop/web/findme/.ubuntu/lib/python3.8/site-packages/gunicorn/workers/base.py", line 146, in load_wsgi
    self.wsgi = self.app.wsgi()
  File "/mnt/c/Users/USER/Desktop/web/findme/.ubuntu/lib/python3.8/site-packages/gunicorn/app/base.py", line 67, in wsgi
    self.callable = self.load()
  File "/mnt/c/Users/USER/Desktop/web/findme/.ubuntu/lib/python3.8/site-packages/gunicorn/app/wsgiapp.py", line 58, in load
    return self.load_wsgiapp()
  File "/mnt/c/Users/USER/Desktop/web/findme/.ubuntu/lib/python3.8/site-packages/gunicorn/app/wsgiapp.py", line 48, in load_wsgiapp
    return util.import_app(self.app_uri)
  File "/mnt/c/Users/USER/Desktop/web/findme/.ubuntu/lib/python3.8/site-packages/gunicorn/util.py", line 371, in import_app
    mod = importlib.import_module(module)
  File "/usr/lib/python3.8/importlib/__init__.py", line 127, in import_module
    return _bootstrap._gcd_import(name[level:], package, level)
  File "<frozen importlib._bootstrap>", line 1014, in _gcd_import
  File "<frozen importlib._bootstrap>", line 991, in _find_and_load
  File "<frozen importlib._bootstrap>", line 975, in _find_and_load_unlocked
  File "<frozen importlib._bootstrap>", line 671, in _load_unlocked
  File "<frozen importlib._bootstrap_external>", line 783, in exec_module
  File "<frozen importlib._bootstrap>", line 219, in _call_with_frames_removed
  File "/mnt/c/Users/USER/Desktop/web/findme/backend/backend/wsgi.py", line 12, in <module>
    from django.core.wsgi import get_wsgi_application
  File "/mnt/c/Users/USER/Desktop/web/findme/.ubuntu/lib/python3.8/site-packages/django/__init__.py", line 1, in <module>
    from django.utils.version import get_version
ModuleNotFoundError: No module named 'django.utils'
[2023-09-30 17:05:46 +0100] [1026] [INFO] Worker exiting (pid: 1026)
[2023-09-30 17:05:46 +0100] [1023] [ERROR] Worker (pid:1026) exited with code 3
Traceback (most recent call last):
  File "/mnt/c/Users/USER/Desktop/web/findme/.ubuntu/lib/python3.8/site-packages/gunicorn/arbiter.py", line 202, in run
    self.manage_workers()
  File "/mnt/c/Users/USER/Desktop/web/findme/.ubuntu/lib/python3.8/site-packages/gunicorn/arbiter.py", line 571, in manage_workers
    self.spawn_workers()
  File "/mnt/c/Users/USER/Desktop/web/findme/.ubuntu/lib/python3.8/site-packages/gunicorn/arbiter.py", line 643, in spawn_workers
    time.sleep(0.1 * random.random())
  File "/mnt/c/Users/USER/Desktop/web/findme/.ubuntu/lib/python3.8/site-packages/gunicorn/arbiter.py", line 242, in handle_chld
    self.reap_workers()
  File "/mnt/c/Users/USER/Desktop/web/findme/.ubuntu/lib/python3.8/site-packages/gunicorn/arbiter.py", line 530, in reap_workers
    raise HaltServer(reason, self.WORKER_BOOT_ERROR)
gunicorn.errors.HaltServer: <HaltServer 'Worker failed to boot.' 3>

During handling of the above exception, another exception occurred:

Traceback (most recent call last):
  File "/mnt/c/Users/USER/Desktop/web/findme/.ubuntu/bin/gunicorn", line 8, in <module>
    sys.exit(run())
  File "/mnt/c/Users/USER/Desktop/web/findme/.ubuntu/lib/python3.8/site-packages/gunicorn/app/wsgiapp.py", line 67, in run
    WSGIApplication("%(prog)s [OPTIONS] [APP_MODULE]").run()
  File "/mnt/c/Users/USER/Desktop/web/findme/.ubuntu/lib/python3.8/site-packages/gunicorn/app/base.py", line 236, in run
    super().run()
  File "/mnt/c/Users/USER/Desktop/web/findme/.ubuntu/lib/python3.8/site-packages/gunicorn/app/base.py", line 72, in run
    Arbiter(self).run()
  File "/mnt/c/Users/USER/Desktop/web/findme/.ubuntu/lib/python3.8/site-packages/gunicorn/arbiter.py", line 229, in run
    self.halt(reason=inst.reason, exit_status=inst.exit_status)
  File "/mnt/c/Users/USER/Desktop/web/findme/.ubuntu/lib/python3.8/site-packages/gunicorn/arbiter.py", line 342, in halt
    self.stop()
  File "/mnt/c/Users/USER/Desktop/web/findme/.ubuntu/lib/python3.8/site-packages/gunicorn/arbiter.py", line 396, in stop
    time.sleep(0.1)
  File "/mnt/c/Users/USER/Desktop/web/findme/.ubuntu/lib/python3.8/site-packages/gunicorn/arbiter.py", line 242, in handle_chld
    self.reap_workers()
  File "/mnt/c/Users/USER/Desktop/web/findme/.ubuntu/lib/python3.8/site-packages/gunicorn/arbiter.py", line 530, in reap_workers
    raise HaltServer(reason, self.WORKER_BOOT_ERROR)
gunicorn.errors.HaltServer: <HaltServer 'Worker failed to boot.' 3>
[2023-09-30 17:24:00 +0100] [1050] [DEBUG] Current configuration:
  config: gunicorn_config.py
  wsgi_app: ./backend.wsgi:application
  bind: ['127.0.0.1:8000']
  backlog: 2048
  workers: 3
  worker_class: sync
  threads: 1
  worker_connections: 1000
  max_requests: 0
  max_requests_jitter: 0
  timeout: 30
  graceful_timeout: 30
  keepalive: 2
  limit_request_line: 4094
  limit_request_fields: 100
  limit_request_field_size: 8190
  reload: True
  reload_engine: auto
  reload_extra_files: []
  spew: False
  check_config: False
  print_config: False
  preload_app: False
  sendfile: None
  reuse_port: False
  chdir: /mnt/c/Users/USER/Desktop/web/findme/backend
  daemon: True
  raw_env: []
  pidfile: ./gunicorn/dev.pid
  worker_tmp_dir: None
  user: 1000
  group: 1000
  umask: 0
  initgroups: False
  tmp_upload_dir: None
  secure_scheme_headers: {'X-FORWARDED-PROTOCOL': 'ssl', 'X-FORWARDED-PROTO': 'https', 'X-FORWARDED-SSL': 'on'}
  forwarded_allow_ips: ['127.0.0.1']
  accesslog: ./gunicorn/dev.log
  disable_redirect_access_to_syslog: False
  access_log_format: %(h)s %(l)s %(u)s %(t)s "%(r)s" %(s)s %(b)s "%(f)s" "%(a)s"
  errorlog: ./gunicorn/dev.log
  loglevel: debug
  capture_output: True
  logger_class: gunicorn.glogging.Logger
  logconfig: None
  logconfig_dict: {}
  logconfig_json: None
  syslog_addr: udp://localhost:514
  syslog: False
  syslog_prefix: None
  syslog_facility: user
  enable_stdio_inheritance: False
  statsd_host: None
  dogstatsd_tags: 
  statsd_prefix: 
  proc_name: None
  default_proc_name: gunicorn
  pythonpath: None
  paste: None
  on_starting: <function OnStarting.on_starting at 0x7f762f9b93a0>
  on_reload: <function OnReload.on_reload at 0x7f762f9b94c0>
  when_ready: <function WhenReady.when_ready at 0x7f762f9b95e0>
  pre_fork: <function Prefork.pre_fork at 0x7f762f9b9700>
  post_fork: <function Postfork.post_fork at 0x7f762f9b9820>
  post_worker_init: <function PostWorkerInit.post_worker_init at 0x7f762f9b9940>
  worker_int: <function WorkerInt.worker_int at 0x7f762f9b9a60>
  worker_abort: <function WorkerAbort.worker_abort at 0x7f762f9b9b80>
  pre_exec: <function PreExec.pre_exec at 0x7f762f9b9ca0>
  pre_request: <function PreRequest.pre_request at 0x7f762f9b9dc0>
  post_request: <function PostRequest.post_request at 0x7f762f9b9e50>
  child_exit: <function ChildExit.child_exit at 0x7f762f9b9f70>
  worker_exit: <function WorkerExit.worker_exit at 0x7f762f9510d0>
  nworkers_changed: <function NumWorkersChanged.nworkers_changed at 0x7f762f9511f0>
  on_exit: <function OnExit.on_exit at 0x7f762f951310>
  ssl_context: <function NewSSLContext.ssl_context at 0x7f762f951430>
  proxy_protocol: False
  proxy_allow_ips: ['127.0.0.1']
  keyfile: None
  certfile: None
  ssl_version: 2
  cert_reqs: 0
  ca_certs: None
  suppress_ragged_eofs: True
  do_handshake_on_connect: False
  ciphers: None
  raw_paste_global_conf: []
  strip_header_spaces: False
[2023-09-30 17:24:00 +0100] [1050] [INFO] Starting gunicorn 21.2.0
[2023-09-30 17:24:00 +0100] [1050] [DEBUG] Arbiter booted
[2023-09-30 17:24:00 +0100] [1050] [INFO] Listening at: http://127.0.0.1:8000 (1050)
[2023-09-30 17:24:00 +0100] [1050] [INFO] Using worker: sync
[2023-09-30 17:24:00 +0100] [1052] [INFO] Booting worker with pid: 1052
[2023-09-30 17:24:00 +0100] [1052] [ERROR] Exception in worker process
Traceback (most recent call last):
  File "/mnt/c/Users/USER/Desktop/web/findme/.ubuntu/lib/python3.8/site-packages/gunicorn/arbiter.py", line 609, in spawn_worker
    worker.init_process()
  File "/mnt/c/Users/USER/Desktop/web/findme/.ubuntu/lib/python3.8/site-packages/gunicorn/workers/base.py", line 134, in init_process
    self.load_wsgi()
  File "/mnt/c/Users/USER/Desktop/web/findme/.ubuntu/lib/python3.8/site-packages/gunicorn/workers/base.py", line 146, in load_wsgi
    self.wsgi = self.app.wsgi()
  File "/mnt/c/Users/USER/Desktop/web/findme/.ubuntu/lib/python3.8/site-packages/gunicorn/app/base.py", line 67, in wsgi
    self.callable = self.load()
  File "/mnt/c/Users/USER/Desktop/web/findme/.ubuntu/lib/python3.8/site-packages/gunicorn/app/wsgiapp.py", line 58, in load
    return self.load_wsgiapp()
  File "/mnt/c/Users/USER/Desktop/web/findme/.ubuntu/lib/python3.8/site-packages/gunicorn/app/wsgiapp.py", line 48, in load_wsgiapp
    return util.import_app(self.app_uri)
  File "/mnt/c/Users/USER/Desktop/web/findme/.ubuntu/lib/python3.8/site-packages/gunicorn/util.py", line 371, in import_app
    mod = importlib.import_module(module)
  File "/usr/lib/python3.8/importlib/__init__.py", line 122, in import_module
    raise TypeError(msg.format(name))
TypeError: the 'package' argument is required to perform a relative import for './backend.wsgi'
[2023-09-30 17:24:01 +0100] [1052] [INFO] Worker exiting (pid: 1052)
[2023-09-30 17:24:01 +0100] [1053] [INFO] Booting worker with pid: 1053
[2023-09-30 17:24:01 +0100] [1050] [ERROR] Worker (pid:1052) exited with code 3
[2023-09-30 17:24:01 +0100] [1053] [ERROR] Exception in worker process
Traceback (most recent call last):
  File "/mnt/c/Users/USER/Desktop/web/findme/.ubuntu/lib/python3.8/site-packages/gunicorn/arbiter.py", line 609, in spawn_worker
    worker.init_process()
  File "/mnt/c/Users/USER/Desktop/web/findme/.ubuntu/lib/python3.8/site-packages/gunicorn/workers/base.py", line 134, in init_process
    self.load_wsgi()
  File "/mnt/c/Users/USER/Desktop/web/findme/.ubuntu/lib/python3.8/site-packages/gunicorn/workers/base.py", line 146, in load_wsgi
    self.wsgi = self.app.wsgi()
  File "/mnt/c/Users/USER/Desktop/web/findme/.ubuntu/lib/python3.8/site-packages/gunicorn/app/base.py", line 67, in wsgi
    self.callable = self.load()
  File "/mnt/c/Users/USER/Desktop/web/findme/.ubuntu/lib/python3.8/site-packages/gunicorn/app/wsgiapp.py", line 58, in load
    return self.load_wsgiapp()
  File "/mnt/c/Users/USER/Desktop/web/findme/.ubuntu/lib/python3.8/site-packages/gunicorn/app/wsgiapp.py", line 48, in load_wsgiapp
    return util.import_app(self.app_uri)
  File "/mnt/c/Users/USER/Desktop/web/findme/.ubuntu/lib/python3.8/site-packages/gunicorn/util.py", line 371, in import_app
    mod = importlib.import_module(module)
  File "/usr/lib/python3.8/importlib/__init__.py", line 122, in import_module
    raise TypeError(msg.format(name))
TypeError: the 'package' argument is required to perform a relative import for './backend.wsgi'
[2023-09-30 17:24:01 +0100] [1053] [INFO] Worker exiting (pid: 1053)
[2023-09-30 17:24:01 +0100] [1050] [ERROR] Worker (pid:1053) exited with code 3
Traceback (most recent call last):
  File "/mnt/c/Users/USER/Desktop/web/findme/.ubuntu/lib/python3.8/site-packages/gunicorn/arbiter.py", line 202, in run
    self.manage_workers()
  File "/mnt/c/Users/USER/Desktop/web/findme/.ubuntu/lib/python3.8/site-packages/gunicorn/arbiter.py", line 571, in manage_workers
    self.spawn_workers()
  File "/mnt/c/Users/USER/Desktop/web/findme/.ubuntu/lib/python3.8/site-packages/gunicorn/arbiter.py", line 643, in spawn_workers
    time.sleep(0.1 * random.random())
  File "/mnt/c/Users/USER/Desktop/web/findme/.ubuntu/lib/python3.8/site-packages/gunicorn/arbiter.py", line 242, in handle_chld
    self.reap_workers()
  File "/mnt/c/Users/USER/Desktop/web/findme/.ubuntu/lib/python3.8/site-packages/gunicorn/arbiter.py", line 530, in reap_workers
    raise HaltServer(reason, self.WORKER_BOOT_ERROR)
gunicorn.errors.HaltServer: <HaltServer 'Worker failed to boot.' 3>

During handling of the above exception, another exception occurred:

Traceback (most recent call last):
  File "/mnt/c/Users/USER/Desktop/web/findme/.ubuntu/bin/gunicorn", line 8, in <module>
    sys.exit(run())
  File "/mnt/c/Users/USER/Desktop/web/findme/.ubuntu/lib/python3.8/site-packages/gunicorn/app/wsgiapp.py", line 67, in run
    WSGIApplication("%(prog)s [OPTIONS] [APP_MODULE]").run()
  File "/mnt/c/Users/USER/Desktop/web/findme/.ubuntu/lib/python3.8/site-packages/gunicorn/app/base.py", line 236, in run
    super().run()
  File "/mnt/c/Users/USER/Desktop/web/findme/.ubuntu/lib/python3.8/site-packages/gunicorn/app/base.py", line 72, in run
    Arbiter(self).run()
  File "/mnt/c/Users/USER/Desktop/web/findme/.ubuntu/lib/python3.8/site-packages/gunicorn/arbiter.py", line 229, in run
    self.halt(reason=inst.reason, exit_status=inst.exit_status)
  File "/mnt/c/Users/USER/Desktop/web/findme/.ubuntu/lib/python3.8/site-packages/gunicorn/arbiter.py", line 342, in halt
    self.stop()
  File "/mnt/c/Users/USER/Desktop/web/findme/.ubuntu/lib/python3.8/site-packages/gunicorn/arbiter.py", line 396, in stop
    time.sleep(0.1)
  File "/mnt/c/Users/USER/Desktop/web/findme/.ubuntu/lib/python3.8/site-packages/gunicorn/arbiter.py", line 242, in handle_chld
    self.reap_workers()
  File "/mnt/c/Users/USER/Desktop/web/findme/.ubuntu/lib/python3.8/site-packages/gunicorn/arbiter.py", line 530, in reap_workers
    raise HaltServer(reason, self.WORKER_BOOT_ERROR)
gunicorn.errors.HaltServer: <HaltServer 'Worker failed to boot.' 3>
[2023-10-01 17:05:35 +0000] [11244] [INFO] Starting gunicorn 21.2.0
[2023-10-01 17:05:35 +0000] [11244] [INFO] Listening at: http://127.0.0.1:8000 (11244)
[2023-10-01 17:05:35 +0000] [11244] [INFO] Using worker: sync
[2023-10-01 17:05:35 +0000] [11248] [INFO] Booting worker with pid: 11248
[2023-10-01 17:05:35 +0000] [11249] [INFO] Booting worker with pid: 11249
[2023-10-01 17:05:35 +0000] [11256] [INFO] Booting worker with pid: 11256
127.0.0.1 - - [01/Oct/2023:17:05:40 +0000] "GET / HTTP/1.1" 302 0 "-" "Mozilla/5.0 (X11; Linux x86_64; rv:102.0) Gecko/20100101 Firefox/102.0"
127.0.0.1 - - [01/Oct/2023:17:05:40 +0000] "GET /graphql HTTP/1.1" 200 2516 "-" "Mozilla/5.0 (X11; Linux x86_64; rv:102.0) Gecko/20100101 Firefox/102.0"
127.0.0.1 - - [01/Oct/2023:17:05:41 +0000] "GET /static/graphene_django/graphiql.js HTTP/1.1" 200 0 "http://127.0.0.1:8000/graphql" "Mozilla/5.0 (X11; Linux x86_64; rv:102.0) Gecko/20100101 Firefox/102.0"
127.0.0.1 - - [01/Oct/2023:17:05:47 +0000] "POST /graphql HTTP/1.1" 200 33207 "http://127.0.0.1:8000/graphql" "Mozilla/5.0 (X11; Linux x86_64; rv:102.0) Gecko/20100101 Firefox/102.0"
127.0.0.1 - - [01/Oct/2023:17:05:47 +0000] "GET /favicon.ico HTTP/1.1" 404 179 "http://127.0.0.1:8000/graphql" "Mozilla/5.0 (X11; Linux x86_64; rv:102.0) Gecko/20100101 Firefox/102.0"
[2023-10-01 17:05:57 +0000] [11414] [INFO] Starting gunicorn 21.2.0

Error: Already running on PID 11244 (or pid file 'gunicorn/dev.pid' is stale)

127.0.0.1 - - [01/Oct/2023:17:06:00 +0000] "GET /graphql HTTP/1.1" 200 2516 "-" "Mozilla/5.0 (X11; Linux x86_64; rv:102.0) Gecko/20100101 Firefox/102.0"
127.0.0.1 - - [01/Oct/2023:17:06:00 +0000] "POST /graphql HTTP/1.1" 200 33207 "http://127.0.0.1:8000/graphql" "Mozilla/5.0 (X11; Linux x86_64; rv:102.0) Gecko/20100101 Firefox/102.0"
127.0.0.1 - - [01/Oct/2023:17:06:01 +0000] "GET /graphql HTTP/1.1" 200 2516 "-" "Mozilla/5.0 (X11; Linux x86_64; rv:102.0) Gecko/20100101 Firefox/102.0"
127.0.0.1 - - [01/Oct/2023:17:06:02 +0000] "POST /graphql HTTP/1.1" 200 33207 "http://127.0.0.1:8000/graphql" "Mozilla/5.0 (X11; Linux x86_64; rv:102.0) Gecko/20100101 Firefox/102.0"
127.0.0.1 - - [01/Oct/2023:17:06:03 +0000] "GET /graphql HTTP/1.1" 200 2516 "-" "Mozilla/5.0 (X11; Linux x86_64; rv:102.0) Gecko/20100101 Firefox/102.0"
127.0.0.1 - - [01/Oct/2023:17:06:03 +0000] "POST /graphql HTTP/1.1" 200 33207 "http://127.0.0.1:8000/graphql" "Mozilla/5.0 (X11; Linux x86_64; rv:102.0) Gecko/20100101 Firefox/102.0"
127.0.0.1 - - [01/Oct/2023:17:06:07 +0000] "GET /graphql HTTP/1.1" 200 2516 "-" "Mozilla/5.0 (X11; Linux x86_64; rv:102.0) Gecko/20100101 Firefox/102.0"
127.0.0.1 - - [01/Oct/2023:17:06:07 +0000] "POST /graphql HTTP/1.1" 200 33207 "http://127.0.0.1:8000/graphql" "Mozilla/5.0 (X11; Linux x86_64; rv:102.0) Gecko/20100101 Firefox/102.0"
127.0.0.1 - - [01/Oct/2023:17:06:09 +0000] "POST /graphql HTTP/1.1" 400 95 "http://127.0.0.1:8000/graphql" "Mozilla/5.0 (X11; Linux x86_64; rv:102.0) Gecko/20100101 Firefox/102.0"
127.0.0.1 - - [01/Oct/2023:17:06:14 +0000] "GET /graphql HTTP/1.1" 200 2516 "-" "Mozilla/5.0 (X11; Linux x86_64; rv:102.0) Gecko/20100101 Firefox/102.0"
127.0.0.1 - - [01/Oct/2023:17:06:15 +0000] "POST /graphql HTTP/1.1" 200 33207 "http://127.0.0.1:8000/graphql" "Mozilla/5.0 (X11; Linux x86_64; rv:102.0) Gecko/20100101 Firefox/102.0"
[2023-10-01 17:07:03 +0000] [11244] [CRITICAL] WORKER TIMEOUT (pid:11248)
[2023-10-01 17:07:03 +0000] [11248] [INFO] Worker exiting (pid: 11248)
[2023-10-01 17:07:04 +0000] [11244] [ERROR] Worker (pid:11248) exited with code 1
[2023-10-01 17:07:04 +0000] [11244] [ERROR] Worker (pid:11248) exited with code 1.
[2023-10-01 17:07:04 +0000] [11855] [INFO] Booting worker with pid: 11855
127.0.0.1 - - [01/Oct/2023:17:07:13 +0000] "GET / HTTP/1.1" 302 0 "-" "Mozilla/5.0 (X11; Linux x86_64; rv:102.0) Gecko/20100101 Firefox/102.0"
127.0.0.1 - - [01/Oct/2023:17:07:13 +0000] "GET /graphql HTTP/1.1" 200 2516 "-" "Mozilla/5.0 (X11; Linux x86_64; rv:102.0) Gecko/20100101 Firefox/102.0"
127.0.0.1 - - [01/Oct/2023:17:07:14 +0000] "GET /static/graphene_django/graphiql.js HTTP/1.1" 304 0 "http://127.0.0.1:8000/graphql" "Mozilla/5.0 (X11; Linux x86_64; rv:102.0) Gecko/20100101 Firefox/102.0"
127.0.0.1 - - [01/Oct/2023:17:07:14 +0000] "POST /graphql HTTP/1.1" 200 33207 "http://127.0.0.1:8000/graphql" "Mozilla/5.0 (X11; Linux x86_64; rv:102.0) Gecko/20100101 Firefox/102.0"
127.0.0.1 - - [01/Oct/2023:17:11:05 +0000] "GET /graphql HTTP/1.1" 200 2516 "-" "Mozilla/5.0 (X11; Linux x86_64; rv:102.0) Gecko/20100101 Firefox/102.0"
127.0.0.1 - - [01/Oct/2023:17:20:33 +0000] "GET / HTTP/1.1" 302 0 "-" "Mozilla/5.0 (X11; Linux x86_64; rv:102.0) Gecko/20100101 Firefox/102.0"
127.0.0.1 - - [01/Oct/2023:17:20:33 +0000] "GET /graphql HTTP/1.1" 200 2516 "-" "Mozilla/5.0 (X11; Linux x86_64; rv:102.0) Gecko/20100101 Firefox/102.0"
127.0.0.1 - - [01/Oct/2023:17:20:34 +0000] "GET /static/graphene_django/graphiql.js HTTP/1.1" 304 0 "http://127.0.0.1:8000/graphql" "Mozilla/5.0 (X11; Linux x86_64; rv:102.0) Gecko/20100101 Firefox/102.0"
127.0.0.1 - - [01/Oct/2023:17:20:34 +0000] "POST /graphql HTTP/1.1" 200 33207 "http://127.0.0.1:8000/graphql" "Mozilla/5.0 (X11; Linux x86_64; rv:102.0) Gecko/20100101 Firefox/102.0"
127.0.0.1 - - [01/Oct/2023:17:27:52 +0000] "GET / HTTP/1.1" 302 0 "-" "Mozilla/5.0 (X11; Linux x86_64; rv:102.0) Gecko/20100101 Firefox/102.0"
127.0.0.1 - - [01/Oct/2023:17:27:52 +0000] "GET /graphql HTTP/1.1" 200 2516 "-" "Mozilla/5.0 (X11; Linux x86_64; rv:102.0) Gecko/20100101 Firefox/102.0"
127.0.0.1 - - [01/Oct/2023:17:27:53 +0000] "GET /static/graphene_django/graphiql.js HTTP/1.1" 304 0 "http://127.0.0.1:8000/graphql" "Mozilla/5.0 (X11; Linux x86_64; rv:102.0) Gecko/20100101 Firefox/102.0"
127.0.0.1 - - [01/Oct/2023:17:27:53 +0000] "POST /graphql HTTP/1.1" 200 33207 "http://127.0.0.1:8000/graphql" "Mozilla/5.0 (X11; Linux x86_64; rv:102.0) Gecko/20100101 Firefox/102.0"
127.0.0.1 - - [01/Oct/2023:17:36:48 +0000] "GET /graphql HTTP/1.1" 200 2516 "-" "Mozilla/5.0 (X11; Linux x86_64; rv:102.0) Gecko/20100101 Firefox/102.0"
127.0.0.1 - - [01/Oct/2023:17:36:48 +0000] "GET /static/graphene_django/graphiql.js HTTP/1.1" 304 0 "http://127.0.0.1:8000/graphql" "Mozilla/5.0 (X11; Linux x86_64; rv:102.0) Gecko/20100101 Firefox/102.0"
127.0.0.1 - - [01/Oct/2023:17:36:48 +0000] "POST /graphql HTTP/1.1" 200 33207 "http://127.0.0.1:8000/graphql" "Mozilla/5.0 (X11; Linux x86_64; rv:102.0) Gecko/20100101 Firefox/102.0"
